Workbook

Sheet Cover
B2: Delta Electronics, Inc. (2308.TW)
B3: Initiation of coverage - financial model
B4: Student research for educational purposes only. Not investment advice.
B6: Company | C6: Delta Electronics, Inc.
B7: Ticker / exchange | C7: 2308 / Taiwan Stock Exchange
B8: Units | C8: NT$ million unless stated (reported in NT$ thousands, Taiwan IFRS)
B9: Latest reported period | C9: 1H26 - six months to 30 June 2026 (reviewed)
B10: Forecast base period | C10: 9M26 once Q3 2026 results are published, ~29-30 Oct 2026 (decision D2)
B11: Share price and date | C11: Set in M4 (yfinance, 2308.TW)
B12: Rating | C12: [ANALYST TO REVIEW] - set in M5
B13: 12-month price target | C13: [ANALYST TO REVIEW] - set in M4/M5
B14: Scenario | C14: =Assumptions!B3 -> Base
B15: Model status | C15: M2 - historical model FY2021A-1H26A; forecasts added in M3
B16: Last updated | C16: 2026-10-16
B18: ALL CHECKS PASS | C18: =Checks!L36 -> TRUE
B20: Key historicals (NT$ m)
D21: FY2023A | E21: FY2024A | F21: FY2025A | G21: 1H26A
B22: Revenue | D22: =IS!E9 -> 401226.5 | E22: =IS!F9 -> 421147.56 | F22: =IS!G9 -> 554885.17 | G22: =IS!J9 -> 342608.73
B23: EBIT margin | D23: =IS!E40 -> 0.10206165 | E23: =IS!F40 -> 0.11314744 | F23: =IS!G40 -> 0.15126026 | G23: =IS!J40 -> 0.17217117
B24: EPS, basic (NT$) | D24: =IS!E29 -> 12.85548 | E24: =IS!F29 -> 13.562267 | F24: =IS!G29 -> 23.14048 | G24: =IS!J29 -> 17.590171
B25: Free cash flow | D25: =CF!E42 -> 42786.756 | E25: =CF!F42 -> 37820.576 | F25: =CF!G42 -> 51321.494 | G25: =CF!J42 -> 35283.84
B26: Net debt / (net cash) | D26: =BS!E41 -> -35324.569 | E26: =BS!F41 -> -57362.673 | F26: =BS!G41 -> -81084.588 | G26: =BS!J41 -> -115960.82
B28: Sheet guide
B29: Assumptions | C29: Scenario selector; every forecast driver (M3) with its historical reference
B30: Historicals | C30: Extracted as-reported figures (inputs), FY2021A-FY2025A, 1H25A, 1H26A
B31: Segments | C31: Segment revenue and profit; AI data-centre anchors
B32: IS / BS / CF | C32: Three statements built by formula from Historicals
B33: Schedules | C33: Working capital, PP&E, debt and interest, tax, dividends, returns
B34: Checks | C34: Integrity tests; all must be TRUE
B36: Colour key
B37: Blue: hard-coded input (sourced in data/sources.csv)
B38: Black: formula
B39: Green: link to another sheet
B40: Yellow fill: key input for the analyst

Sheet Assumptions
A1: Assumptions
A2: All forecast drivers live on this sheet. M2: scenario selector and the historical reference for each driver. M3 adds FY2026E-FY2030E inputs with Bear / Base / Bull columns, set by the analyst.
A3: Scenario (select) | B3: Base
A4: Scenario index (1 Bear, 2 Base, 3 Bull) | B4: =MATCH(B3,{"Bear","Base","Bull"},0) -> 2
A5: NT$ million | B5: Note / source | C5: FY2021A | D5: FY2022A | E5: FY2023A | F5: FY2024A | G5: FY2025A | L5: Average
C6: 31-Dec-21 | D6: 31-Dec-22 | E6: 31-Dec-23 | F6: 31-Dec-24 | G6: 31-Dec-25 | L6: FY23-25 avail.
A9: Revenue growth - historical reference
A10: Power Electronics | B10: Segments sheet | D10: =Segments!D24 -> 0.21358267 | F10: =Segments!F24 -> 0.096007334 | G10: =Segments!G24 -> 0.25256125 | L10: =AVERAGE(E10:G10) -> 0.17428429
A11: Infrastructure | B11: Segments sheet | D11: =Segments!D25 -> 0.25969069 | E11: =Segments!E25 -> -0.038591908 | F11: =Segments!F25 -> 0.020690258 | G11: =Segments!G25 -> 0.81586396 | L11: =AVERAGE(E11:G11) -> 0.26598744
A12: Automation | B12: Segments sheet | D12: =Segments!D26 -> 0.18826417 | E12: =Segments!E26 -> -0.0041038922 | F12: =Segments!F26 -> -0.034848647 | G12: =Segments!G26 -> 0.048458806 | L12: =AVERAGE(E12:G12) -> 0.0031687554
A13: Mobility | B13: Segments sheet | F13: =Segments!F27 -> -0.0050362807 | G13: =Segments!G27 -> -0.15988697 | L13: =AVERAGE(E13:G13) -> -0.082461627
A14: Group | B14: IS sheet | D14: =IS!D36 -> 0.22173177 | E14: =IS!E36 -> 0.043655833 | F14: =IS!F36 -> 0.049650399 | G14: =IS!G36 -> 0.31755523 | L14: =AVERAGE(E14:G14) -> 0.13695382
A16: Margins and costs - historical reference
A17: Gross margin | B17: IS sheet | C17: =IS!C37 -> 0.28667882 | D17: =IS!D37 -> 0.28813758 | E17: =IS!E37 -> 0.2921368 | F17: =IS!F37 -> 0.3243048 | G17: =IS!G37 -> 0.34269533 | L17: =AVERAGE(E17:G17) -> 0.31971231
A18: R&D % revenue | B18: IS sheet | C18: =IS!C38 -> 0.086447453 | D18: =IS!D38 -> 0.082638923 | E18: =IS!E38 -> 0.08984414 | F18: =IS!F38 -> 0.098717828 | G18: =IS!G38 -> 0.087842876 | L18: =AVERAGE(E18:G18) -> 0.092134948
A19: SG&A % revenue | B19: IS sheet | C19: =IS!C39 -> 0.10112026 | D19: =IS!D39 -> 0.097362168 | E19: =IS!E39 -> 0.099913622 | F19: =IS!F39 -> 0.1121233 | G19: =IS!G39 -> 0.1028373 | L19: =AVERAGE(E19:G19) -> 0.10495807
A20: EBIT margin | B20: IS sheet | C20: =IS!C40 -> 0.099674776 | D20: =IS!D40 -> 0.10778917 | E20: =IS!E40 -> 0.10206165 | F20: =IS!F40 -> 0.11314744 | G20: =IS!G40 -> 0.15126026 | L20: =AVERAGE(E20:G20) -> 0.12215645
A21: Effective tax rate | B21: IS sheet | C21: =IS!C42 -> 0.20007872 | D21: =IS!D42 -> 0.19699341 | E21: =IS!E42 -> 0.20068504 | F21: =IS!F42 -> 0.21288891 | G21: =IS!G42 -> 0.22681912 | L21: =AVERAGE(E21:G21) -> 0.21346436
A22: NCI % net income | B22: Schedules sheet | C22: =Schedules!C57 -> 0.059753573 | D22: =Schedules!D57 -> 0.11692143 | E22: =Schedules!E57 -> 0.14114327 | F22: =Schedules!F57 -> 0.12781338 | G22: =Schedules!G57 -> 0.11522423 | L22: =AVERAGE(E22:G22) -> 0.12806029
A24: Working capital (days) - historical reference
A25: DSO | B25: Schedules sheet | C25: =Schedules!C14 -> 82.190051 | D25: =Schedules!D14 -> 82.787667 | E25: =Schedules!E14 -> 72.212521 | F25: =Schedules!F14 -> 77.932265 | G25: =Schedules!G14 -> 80.064396 | L25: =AVERAGE(E25:G25) -> 76.736394
A26: DIO | B26: Schedules sheet | C26: =Schedules!C15 -> 107.49817 | D26: =Schedules!D15 -> 106.48998 | E26: =Schedules!E15 -> 97.962589 | F26: =Schedules!F15 -> 107.55823 | G26: =Schedules!G15 -> 101.55382 | L26: =AVERAGE(E26:G26) -> 102.35821
A27: DPO | B27: Schedules sheet | C27: =Schedules!C16 -> 88.736983 | D27: =Schedules!D16 -> 83.64511 | E27: =Schedules!E16 -> 68.80559 | F27: =Schedules!F16 -> 88.789117 | G27: =Schedules!G16 -> 94.521787 | L27: =AVERAGE(E27:G27) -> 84.038831
A29: Capex, D&A and financing - historical reference
A30: Total capex % revenue | B30: Schedules sheet | C30: =Schedules!C28 -> 0.077313396 | D30: =Schedules!D28 -> 0.058369017 | E30: =Schedules!E28 -> 0.070532871 | F30: =Schedules!F28 -> 0.083282879 | G30: =Schedules!G28 -> 0.084977559 | L30: =AVERAGE(E30:G30) -> 0.07959777
A31: Depreciation % opening PP&E | B31: Schedules sheet | D31: =Schedules!D29 -> 0.19606808 | E31: =Schedules!E29 -> 0.20375291 | F31: =Schedules!F29 -> 0.21524704 | G31: =Schedules!G29 -> 0.20760726 | L31: =AVERAGE(E31:G31) -> 0.20886907
A32: D&A % revenue | B32: Schedules sheet | C32: =Schedules!C30 -> 0.054505544 | D32: =Schedules!D30 -> 0.049256092 | E32: =Schedules!E30 -> 0.053809389 | F32: =Schedules!F30 -> 0.059400017 | G32: =Schedules!G30 -> 0.050170851 | L32: =AVERAGE(E32:G32) -> 0.054460086
A33: Cost of debt | B33: Schedules sheet | D33: =Schedules!D42 -> 0.012065209 | E33: =Schedules!E42 -> 0.02257696 | F33: =Schedules!F42 -> 0.025423123 | G33: =Schedules!G42 -> 0.032009787 | L33: =AVERAGE(E33:G33) -> 0.026669957
A34: Yield on cash | B34: Schedules sheet | D34: =Schedules!D46 -> 0.010944393 | E34: =Schedules!E46 -> 0.027786265 | F34: =Schedules!F46 -> 0.033250804 | G34: =Schedules!G46 -> 0.027670441 | L34: =AVERAGE(E34:G34) -> 0.02956917
A35: Dividend payout | B35: Schedules sheet | D35: =Schedules!D56 -> 0.53315114 | E35: =Schedules!E56 -> 0.7824654 | F35: =Schedules!F56 -> 0.50017484 | G35: =Schedules!G56 -> 0.51613788 | L35: =AVERAGE(E35:G35) -> 0.59959271
A37: Forecast inputs (FY2026E-FY2030E, Bear / Base / Bull) are added in M3. Base period moves to 9M26 when Q3 2026 results are published (decision D2).

Sheet Historicals
A1: Historical financial statements - as reported
A2: NT$ million (reported in NT$ thousands, shown /1,000). Taiwan IFRS, consolidated. Blue = hard-coded from the filings; page reference for every value in data/sources.csv.
A3: Source document | C3: 2021_annual | D3: 2022_annual | E3: 2023_annual | F3: 2024_annual | G3: 2025_annual | I3: 2026q2 (comparative) | J3: 2026q2
I4: Interim (six months)
A5: NT$ million | B5: Note / source | C5: FY2021A | D5: FY2022A | E5: FY2023A | F5: FY2024A | G5: FY2025A | I5: 1H25A | J5: 1H26A
C6: 31-Dec-21 | D6: 31-Dec-22 | E6: 31-Dec-23 | F6: 31-Dec-24 | G6: 31-Dec-25 | I6: 30-Jun-25 | J6: 30-Jun-26
A8: Income statement
A9: Operating revenue | B9: extracted; see sources.csv | C9: 314670.8 | D9: 384443.31 | E9: 401226.5 | F9: 421147.56 | G9: 554885.17 | I9: 242954.49 | J9: 342608.73
A10: Operating costs | B10: extracted; see sources.csv | C10: -224461.35 | D10: -273670.74 | E10: -284013.47 | F10: -284567.38 | G10: -364728.61 | I10: -161117.21 | J10: -218339.91
A11: Gross profit (reported) | B11: extracted; see sources.csv | C11: 90209.451 | D11: 110772.56 | E11: 117213.03 | F11: 136580.17 | G11: 190156.56 | I11: 81837.285 | J11: 124268.82
A12: Selling expenses | B12: extracted; see sources.csv | C12: -19441.53 | D12: -22533.664 | E12: -24136.041 | F12: -27828.065 | G12: -34726.493 | I12: -15547.743 | J12: -21390.676
A13: General and administrative expenses | B13: extracted; see sources.csv | C13: -12378.064 | D13: -14896.57 | E13: -15951.952 | F13: -19392.387 | G13: -22336.401 | I13: -10347.947 | J13: -13390.599
A14: Research and development expenses | B14: extracted; see sources.csv | C14: -27202.489 | D14: -31769.981 | E14: -36047.85 | F14: -41574.772 | G14: -48742.709 | I14: -22908.678 | J14: -29438.966
A15: Expected credit impairment (loss) gain | B15: extracted; see sources.csv | C15: 177.373 | D15: -133.524 | E15: -127.348 | F15: -133.182 | G15: -418.881 | I15: -328.143 | J15: -1061.235
A16: Total operating expenses (reported) | B16: extracted; see sources.csv | C16: -58844.71 | D16: -69333.739 | E16: -76263.191 | F16: -88928.406 | G16: -106224.48 | I16: -49132.511 | J16: -65281.476
A17: Operating profit (reported) | B17: extracted; see sources.csv | C17: 31364.741 | D17: 41438.824 | E17: 40949.837 | F17: 47651.768 | G17: 83932.074 | I17: 32704.774 | J17: 58987.345
A18: Interest income | B18: extracted; see sources.csv | C18: 429.643 | D18: 609.613 | E18: 2070.115 | F18: 3406.797 | G18: 3716.575 | I18: 1862.451 | J18: 1920.977
A19: Other income | B19: extracted; see sources.csv | C19: 3090.291 | D19: 3360.096 | E19: 4440.902 | F19: 4756.442 | G19: 5512.038 | I19: 2540.869 | J19: 3063.375
A20: Other gains and losses | B20: extracted; see sources.csv | C20: 1038.291 | D20: 1197.074 | E20: 2343.695 | F20: -2879.167 | G20: -3083.349 | I20: -850.207 | J20: 3225.012
... A30: Diluted EPS (NT$) | B30: extracted; see sources.csv | C30: 10.27 | D30: 12.52 | E30: 12.8 | F30: 13.51 | G30: 23.08 | I30: 9.28 | J30: 17.57
A32: Balance sheet (period end)
A33: Cash and cash equivalents | B33: extracted; see sources.csv | C33: 49855.053 | D33: 61546.836 | E33: 87455.916 | F33: 117459.25 | G33: 151172.17 | I33: 139527.97 | J33: 182350.2
A34: Financial assets at FVTPL - current | B34: extracted; see sources.csv | C34: 1085.729 | D34: 1759.612 | E34: 4904.074 | F34: 4180.276 | G34: 3724.428 | I34: 3697.138 | J34: 3944.461
A35: Financial assets at FVOCI - current | B35: extracted; see sources.csv | C35: 0 | D35: 0 | E35: 0 | F35: 0 | G35: 0 | I35: 0 | J35: 0
A36: Financial assets at amortised cost - current | B36: extracted; see sources.csv | C36: 327.238 | D36: 265.382 | E36: 259.567 | F36: 153.016 | G36: 216.27 | I36: 124.286 | J36: 304.394
A37: Contract assets - current | B37: extracted; see sources.csv | C37: 3589.313 | D37: 4135.672 | E37: 5529.06 | F37: 5849.578 | G37: 6729.264 | I37: 6510.21 | J37: 7217.051
A38: Notes receivable, net | B38: extracted; see sources.csv | C38: 3420.633 | D38: 3123.642 | E38: 2245.939 | F38: 2428.199 | G38: 2482.652 | I38: 1677.296 | J38: 2935.688
A39: Accounts receivable, net | B39: extracted; see sources.csv | C39: 67436.377 | D39: 84074.069 | E39: 77127.923 | F39: 87480.791 | G39: 119225.02 | I39: 89759.182 | J39: 140007.91
A40: Accounts receivable - related parties | B40: extracted; see sources.csv | C40: 0 | D40: 0 | E40: 5.801 | F40: 11.511 | G40: 8.896 | I40: 6.675 | J40: 3.179
A41: Inventories | B41: extracted; see sources.csv | C41: 66107.351 | D41: 79844.364 | E41: 76226.562 | F41: 83856.341 | G41: 101478.31 | I41: 81529.671 | J41: 139394.17
A42: Total current assets (reported) | B42: extracted; see sources.csv | C42: 196878.19 | D42: 240450.47 | E42: 259958.18 | F42: 310924.85 | G42: 395780.79 | I42: 331615.26 | J42: 487049.6
A43: Financial assets at FVTPL - non-current | B43: extracted; see sources.csv | C43: 3351.798 | D43: 2771.627 | E43: 1367.375 | F43: 1461.913 | G43: 1617.073 | I43: 1517.658 | J43: 3075.782
A44: Financial assets at FVOCI - non-current | B44: extracted; see sources.csv | C44: 1587.843 | D44: 1740.553 | E44: 1995.03 | F44: 2088.104 | G44: 1925.901 | I44: 1750.412 | J44: 4554.83
... A69: Total liabilities and equity (reported) | B69: extracted; see sources.csv | C69: 0 | D69: 0 | E69: 457746.58 | F69: 531897.72 | G69: 639618.6 | I69: 546418.92 | J69: 754433.33
A71: Cash flow statement
A72: Profit before tax (cash flow statement) | B72: extracted; see sources.csv | C72: 35627.547 | D72: 46065.298 | E72: 48642.111 | F72: 51315.628 | G72: 87865.996 | I72: 35234.087 | J72: 66092.437
A73: Depreciation | B73: extracted; see sources.csv | C73: 13467.401 | D73: 15020.243 | E73: 17577.068 | F73: 21094.536 | G73: 24022.324 | I73: 11618.541 | J73: 14278.138
A74: Amortisation | B74: extracted; see sources.csv | C74: 3683.902 | D74: 3915.932 | E74: 4012.685 | F74: 3921.636 | G74: 3816.737 | I74: 1960.472 | J74: 1943.872
A75: Change in accounts receivable | B75: extracted; see sources.csv | C75: -7683.037 | D75: -15664.563 | E75: 7245.438 | F75: -10404.087 | G75: -31992.341 | I75: -2524.48 | J75: -21685.625
A76: Change in inventories | B76: extracted; see sources.csv | C76: -20873.744 | D76: -12320.867 | E76: 4132.104 | F76: -7629.779 | G76: -17509.757 | I76: 2390.161 | J76: -37836.259
...

Sheet Segments
A1: Segment revenue and profit
A2: NT$ million. Source: operating segment note, latest restated basis. FY2021-22 are on Delta's old 3-segment basis (Mobility inside Power Electronics), so FY2023 growth is not shown for Power Electronics or Mobility. Infrastructure and Automation were restated by <0.3% and are shown.
I4: Interim (six months)
A5: NT$ million | B5: Note / source | C5: FY2021A | D5: FY2022A | E5: FY2023A | F5: FY2024A | G5: FY2025A | I5: 1H25A | J5: 1H26A
C6: 31-Dec-21 | D6: 31-Dec-22 | E6: 31-Dec-23 | F6: 31-Dec-24 | G6: 31-Dec-25 | I6: 30-Jun-25 | J6: 30-Jun-26
A8: Revenue from external customers
A9: Power Electronics | B9: segment note | C9: 187316.91 | D9: 227324.56 | E9: 203983.32 | F9: 223567.22 | G9: 280031.63 | I9: 124017.98 | J9: 181918.73
A10: Infrastructure | B10: segment note | C10: 81079.663 | D10: 102135.3 | E10: 98193.701 | F10: 100225.35 | G10: 181995.61 | I10: 70058.637 | J10: 114273.58
A11: Automation | B11: segment note | C11: 45881.397 | D11: 54519.22 | E11: 54295.479 | F11: 52403.355 | G11: 54942.759 | I11: 27222.759 | J11: 29890.867
A12: Mobility | B12: in PE before FY2023 | E12: 44278.112 | F12: 44055.115 | G12: 37011.276 | I12: 21344.282 | J12: 16008.867
A13: Others / unallocated | B13: group revenue - segments ('Others') | C13: =IS!C9-SUM(C9:C12) -> 392.826 | D13: =IS!D9-SUM(D9:D12) -> 464.235 | E13: =IS!E9-SUM(E9:E12) -> 475.886 | F13: =IS!F9-SUM(F9:F12) -> 896.515 | G13: =IS!G9-SUM(G9:G12) -> 903.891 | I13: =IS!I9-SUM(I9:I12) -> 310.837 | J13: =IS!J9-SUM(J9:J12) -> 516.691
A14: Group revenue | C14: =SUM(C9:C13) -> 314670.8 | D14: =SUM(D9:D13) -> 384443.31 | E14: =SUM(E9:E13) -> 401226.5 | F14: =SUM(F9:F13) -> 421147.56 | G14: =SUM(G9:G13) -> 554885.17 | I14: =SUM(I9:I13) -> 242954.49 | J14: =SUM(J9:J13) -> 342608.73
A16: Segment operating profit
A17: Power Electronics | B17: segment note | C17: 21443.466 | D17: 32129.078 | E17: 34514.792 | F17: 40993.404 | G17: 56181.417 | I17: 23571.797 | J17: 39007.837
A18: Infrastructure | B18: segment note | C18: 4945.086 | D18: 6162.619 | E18: 3942.878 | F18: 5529.801 | G18: 28388.614 | I18: 8867.555 | J18: 21444.51
A19: Automation | B19: segment note | C19: 4976.189 | D19: 3147.127 | E19: 1455.053 | F19: 919.219 | G19: 556.149 | I19: 669.363 | J19: -334.243
A20: Mobility | B20: segment note | E20: 1037.114 | F20: 209.344 | G20: -1194.106 | I20: -403.941 | J20: -1130.759
A21: Total segment profit | B21: equals EBIT (tested on Checks) | C21: =SUM(C17:C20) -> 31364.741 | D21: =SUM(D17:D20) -> 41438.824 | E21: =SUM(E17:E20) -> 40949.837 | F21: =SUM(F17:F20) -> 47651.768 | G21: =SUM(G17:G20) -> 83932.074 | I21: =SUM(I17:I20) -> 32704.774 | J21: =SUM(J17:J20) -> 58987.345
A23: Revenue growth (y/y)
A24: Power Electronics | D24: =D9/C9-1 -> 0.21358267 | F24: =F9/E9-1 -> 0.096007334 | G24: =G9/F9-1 -> 0.25256125 | J24: =J9/I9-1 -> 0.46687384
A25: Infrastructure | D25: =D10/C10-1 -> 0.25969069 | E25: =E10/D10-1 -> -0.038591908 | F25: =F10/E10-1 -> 0.020690258 | G25: =G10/F10-1 -> 0.81586396 | J25: =J10/I10-1 -> 0.63111339
A26: Automation | D26: =D11/C11-1 -> 0.18826417 | E26: =E11/D11-1 -> -0.0041038922 | F26: =F11/E11-1 -> -0.034848647 | G26: =G11/F11-1 -> 0.048458806 | J26: =J11/I11-1 -> 0.098010198
A27: Mobility | F27: =F12/E12-1 -> -0.0050362807 | G27: =G12/F12-1 -> -0.15988697 | J27: =J12/I12-1 -> -0.24996929
A28: Group | D28: =D14/C14-1 -> 0.22173177 | E28: =E14/D14-1 -> 0.043655833 | F28: =F14/E14-1 -> 0.049650399 | G28: =G14/F14-1 -> 0.31755523 | J28: =J14/I14-1 -> 0.41017657
A30: Revenue mix (% of group)
A31: Power Electronics | C31: =C9/C14 -> 0.59527898 | D31: =D9/D14 -> 0.5913084 | E31: =E9/E14 -> 0.50839943 | F31: =F9/F14 -> 0.53085246 | G31: =G9/G14 -> 0.50466592 | I31: =I9/I14 -> 0.51045764 | J31: =J9/J14 -> 0.530981
A32: Infrastructure | C32: =C10/C14 -> 0.25766504 | D32: =D10/D14 -> 0.26567063 | E32: =E10/E14 -> 0.24473384 | F32: =F10/F14 -> 0.23798156 | G32: =G10/G14 -> 0.32798788 | I32: =I10/I14 -> 0.28836115 | J32: =J10/J14 -> 0.3335396
A33: Automation | C33: =C11/C14 -> 0.14580761 | D33: =D11/D14 -> 0.14181342 | E33: =E11/E14 -> 0.13532376 | F33: =F11/F14 -> 0.12442992 | G33: =G11/G14 -> 0.099016449 | I33: =I11/I14 -> 0.1120488 | J33: =J11/J14 -> 0.087244907
A34: Mobility | E34: =E12/E14 -> 0.1103569 | F34: =F12/F14 -> 0.10460731 | G34: =G12/G14 -> 0.066700784 | I34: =I12/I14 -> 0.087853004 | J34: =J12/J14 -> 0.046726383
A36: Segment margin (profit / revenue)
A37: Power Electronics | C37: =C17/C9 -> 0.11447694 | D37: =D17/D9 -> 0.14133571 | E37: =E17/E9 -> 0.16920399 | F37: =F17/F9 -> 0.18336053 | G37: =G17/G9 -> 0.20062525 | I37: =I17/I9 -> 0.19006758 | J37: =J17/J9 -> 0.21442453
A38: Infrastructure | C38: =C18/C10 -> 0.060990461 | D38: =D18/D10 -> 0.060337799 | E38: =E18/E10 -> 0.040154083 | F38: =F18/F10 -> 0.055173674 | G38: =G18/G10 -> 0.15598516 | I38: =I18/I10 -> 0.12657333 | J38: =J18/J10 -> 0.18765939
A39: Automation | C39: =C19/C11 -> 0.10845766 | D39: =D19/D11 -> 0.057725092 | E39: =E19/E11 -> 0.026798787 | F39: =F19/F11 -> 0.017541224 | G39: =G19/G11 -> 0.010122335 | I39: =I19/I11 -> 0.02458836 | J39: =J19/J11 -> -0.011182111
A40: Mobility | E40: =E20/E12 -> 0.023422724 | F40: =F20/F12 -> 0.0047518659 | G40: =G20/G12 -> -0.032263303 | I40: =I20/I12 -> -0.018925022 | J40: =J20/J12 -> -0.070633293
A41: Group EBIT margin | C41: =C21/C14 -> 0.099674776 | D41: =D21/D14 -> 0.10778917 | E41: =E21/E14 -> 0.10206165 | F41: =F21/F14 -> 0.11314744 | G41: =G21/G14 -> 0.15126026 | I41: =I21/I14 -> 0.13461276 | J41: =J21/J14 -> 0.17217117
A44: AI data-centre anchors (management disclosures, decision D1) - the AI line is built from these in M3
A45: Anchor | B45: Source | C45: Period | D45: Share of revenue | E45: Qualifier | F45: Implied NT$ m
A46: Liquid-cooling products | B46: 2Q26 transcript p.12 | C46: FY2025 | D46: 0.1 | E46: approx. | F46: =D46*IS!G9 -> 55488.517
A47: Liquid-cooling products | B47: 2Q26 transcript p.12 | C47: FY2026E | D47: 0.12 | E47: more than | F47: M3 forecast
A48: AI-related products | B48: 2Q26 transcript p.12 | C48: FY2026E | D48: 0.25 | E48: more than | F48: M3 forecast
...

Sheet IS
A1: Income statement
A2: NT$ million unless stated. Lines link to Historicals; subtotals are recomputed (not copied) and tested against reported figures on the Checks sheet.
I4: Interim (six months)
A5: NT$ million | B5: Note / source | C5: FY2021A | D5: FY2022A | E5: FY2023A | F5: FY2024A | G5: FY2025A | I5: 1H25A | J5: 1H26A
C6: 31-Dec-21 | D6: 31-Dec-22 | E6: 31-Dec-23 | F6: 31-Dec-24 | G6: 31-Dec-25 | I6: 30-Jun-25 | J6: 30-Jun-26
A8: Income statement
A9: Revenue | C9: =Historicals!C9 -> 314670.8 | D9: =Historicals!D9 -> 384443.31 | E9: =Historicals!E9 -> 401226.5 | F9: =Historicals!F9 -> 421147.56 | G9: =Historicals!G9 -> 554885.17 | I9: =Historicals!I9 -> 242954.49 | J9: =Historicals!J9 -> 342608.73
A10: Cost of revenue | C10: =Historicals!C10 -> -224461.35 | D10: =Historicals!D10 -> -273670.74 | E10: =Historicals!E10 -> -284013.47 | F10: =Historicals!F10 -> -284567.38 | G10: =Historicals!G10 -> -364728.61 | I10: =Historicals!I10 -> -161117.21 | J10: =Historicals!J10 -> -218339.91
A11: Gross profit | C11: =C9+C10 -> 90209.451 | D11: =D9+D10 -> 110772.56 | E11: =E9+E10 -> 117213.03 | F11: =F9+F10 -> 136580.17 | G11: =G9+G10 -> 190156.56 | I11: =I9+I10 -> 81837.285 | J11: =J9+J10 -> 124268.82
A12: Selling expenses | C12: =Historicals!C12 -> -19441.53 | D12: =Historicals!D12 -> -22533.664 | E12: =Historicals!E12 -> -24136.041 | F12: =Historicals!F12 -> -27828.065 | G12: =Historicals!G12 -> -34726.493 | I12: =Historicals!I12 -> -15547.743 | J12: =Historicals!J12 -> -21390.676
A13: General and administrative | C13: =Historicals!C13 -> -12378.064 | D13: =Historicals!D13 -> -14896.57 | E13: =Historicals!E13 -> -15951.952 | F13: =Historicals!F13 -> -19392.387 | G13: =Historicals!G13 -> -22336.401 | I13: =Historicals!I13 -> -10347.947 | J13: =Historicals!J13 -> -13390.599
A14: Research and development | C14: =Historicals!C14 -> -27202.489 | D14: =Historicals!D14 -> -31769.981 | E14: =Historicals!E14 -> -36047.85 | F14: =Historicals!F14 -> -41574.772 | G14: =Historicals!G14 -> -48742.709 | I14: =Historicals!I14 -> -22908.678 | J14: =Historicals!J14 -> -29438.966
A15: Expected credit loss | C15: =Historicals!C15 -> 177.373 | D15: =Historicals!D15 -> -133.524 | E15: =Historicals!E15 -> -127.348 | F15: =Historicals!F15 -> -133.182 | G15: =Historicals!G15 -> -418.881 | I15: =Historicals!I15 -> -328.143 | J15: =Historicals!J15 -> -1061.235
A16: Total operating expenses | C16: =SUM(C12:C15) -> -58844.71 | D16: =SUM(D12:D15) -> -69333.739 | E16: =SUM(E12:E15) -> -76263.191 | F16: =SUM(F12:F15) -> -88928.406 | G16: =SUM(G12:G15) -> -106224.48 | I16: =SUM(I12:I15) -> -49132.511 | J16: =SUM(J12:J15) -> -65281.476
A17: Operating profit (EBIT) | C17: =C11+C16 -> 31364.741 | D17: =D11+D16 -> 41438.824 | E17: =E11+E16 -> 40949.837 | F17: =F11+F16 -> 47651.768 | G17: =G11+G16 -> 83932.074 | I17: =I11+I16 -> 32704.774 | J17: =J11+J16 -> 58987.345
A18: Interest income | C18: =Historicals!C18 -> 429.643 | D18: =Historicals!D18 -> 609.613 | E18: =Historicals!E18 -> 2070.115 | F18: =Historicals!F18 -> 3406.797 | G18: =Historicals!G18 -> 3716.575 | I18: =Historicals!I18 -> 1862.451 | J18: =Historicals!J18 -> 1920.977
A19: Finance costs | C19: =Historicals!C21 -> -295.157 | D19: =Historicals!D21 -> -571.44 | E19: =Historicals!E21 -> -1170.718 | F19: =Historicals!F21 -> -1547.313 | G19: =Historicals!G21 -> -2216.008 | I19: =Historicals!I21 -> -1037.29 | J19: =Historicals!J21 -> -1094.432
A20: Other non-operating items | B20: other income, gains/losses, associates | C20: =Historicals!C19+Historicals!C20+Historicals!C22 -> 4128.32 | D20: =Historicals!D19+Historicals!D20+Historicals!D22 -> 4588.301 | E20: =Historicals!E19+Historicals!E20+Historicals!E22 -> 6792.877 | F20: =Historicals!F19+Historicals!F20+Historicals!F22 -> 1804.376 | G20: =Historicals!G19+Historicals!G20+Historicals!G22 -> 2433.355 | I20: =Historicals!I19+Historicals!I20+Historicals!I22 -> 1704.152 | J20: =Historicals!J19+Historicals!J20+Historicals!J22 -> 6278.547
A21: Total non-operating income | C21: =SUM(C18:C20) -> 4262.806 | D21: =SUM(D18:D20) -> 4626.474 | E21: =SUM(E18:E20) -> 7692.274 | F21: =SUM(F18:F20) -> 3663.86 | G21: =SUM(G18:G20) -> 3933.922 | I21: =SUM(I18:I20) -> 2529.313 | J21: =SUM(J18:J20) -> 7105.092
A22: Profit before tax | C22: =C17+C21 -> 35627.547 | D22: =D17+D21 -> 46065.298 | E22: =E17+E21 -> 48642.111 | F22: =F17+F21 -> 51315.628 | G22: =G17+G21 -> 87865.996 | I22: =I17+I21 -> 35234.087 | J22: =J17+J21 -> 66092.437
A23: Income tax | C23: =Historicals!C25 -> -7128.314 | D23: =Historicals!D25 -> -9074.56 | E23: =Historicals!E25 -> -9761.744 | F23: =Historicals!F25 -> -10924.528 | G23: =Historicals!G25 -> -19929.688 | I23: =Historicals!I25 -> -7857.035 | J23: =Historicals!J25 -> -15088.837
A24: Net income | C24: =C22+C23 -> 28499.233 | D24: =D22+D23 -> 36990.738 | E24: =E22+E23 -> 38880.367 | F24: =F22+F23 -> 40391.1 | G24: =G22+G23 -> 67936.308 | I24: =I22+I23 -> 27377.052 | J24: =J22+J23 -> 51003.6
A25: Less: non-controlling interests | C25: =-Historicals!C28 -> -1702.931 | D25: =-Historicals!D28 -> -4325.01 | E25: =-Historicals!E28 -> -5487.702 | F25: =-Historicals!F28 -> -5162.523 | G25: =-Historicals!G28 -> -7827.909 | I25: =-Historicals!I28 -> -3198.066 | J25: =-Historicals!J28 -> -5312.369
A26: Net income to owners of the parent | C26: =C24+C25 -> 26796.302 | D26: =D24+D25 -> 32665.728 | E26: =E24+E25 -> 33392.665 | F26: =F24+F25 -> 35228.577 | G26: =G24+G25 -> 60108.399 | I26: =I24+I25 -> 24178.986 | J26: =J24+J25 -> 45691.231
A28: Shares outstanding, period end (m) | B28: share capital / NT$10 par | C28: =Historicals!C65/Historicals!C101 -> 2597.5433 | D28: =Historicals!D65/Historicals!D101 -> 2597.5433 | E28: =Historicals!E65/Historicals!E101 -> 2597.5433 | F28: =Historicals!F65/Historicals!F101 -> 2597.5433 | G28: =Historicals!G65/Historicals!G101 -> 2597.5433 | I28: =Historicals!I65/Historicals!I101 -> 2597.5433 | J28: =Historicals!J65/Historicals!J101 -> 2597.5433
A29: EPS, basic (NT$) | B29: computed; reported EPS on Historicals | C29: =C26/C28 -> 10.316017 | D29: =D26/D28 -> 12.575624 | E29: =E26/E28 -> 12.85548 | F29: =F26/F28 -> 13.562267 | G29: =G26/G28 -> 23.14048 | I29: =I26/I28 -> 9.3084054 | J29: =J26/J28 -> 17.590171
A31: Memo
A32: Depreciation and amortisation | B32: from cash flow statement | C32: =Historicals!C73+Historicals!C74 -> 17151.303 | D32: =Historicals!D73+Historicals!D74 -> 18936.175 | E32: =Historicals!E73+Historicals!E74 -> 21589.753 | F32: =Historicals!F73+Historicals!F74 -> 25016.172 | G32: =Historicals!G73+Historicals!G74 -> 27839.061 | I32: =Historicals!I73+Historicals!I74 -> 13579.013 | J32: =Historicals!J73+Historicals!J74 -> 16222.01
A33: EBITDA (EBIT + D&A) | B33: operating definition (decision D3) | C33: =C17+C32 -> 48516.044 | D33: =D17+D32 -> 60374.999 | E33: =E17+E32 -> 62539.59 | F33: =F17+F32 -> 72667.94 | G33: =G17+G32 -> 111771.13 | I33: =I17+I32 -> 46283.787 | J33: =J17+J32 -> 75209.355
A35: Ratios
A36: Revenue growth (y/y) | B36: 1H26 vs 1H25 | D36: =D9/C9-1 -> 0.22173177 | E36: =E9/D9-1 -> 0.043655833 | F36: =F9/E9-1 -> 0.049650399 | G36: =G9/F9-1 -> 0.31755523 | J36: =J9/I9-1 -> 0.41017657
A37: Gross margin | C37: =C11/C9 -> 0.28667882 | D37: =D11/D9 -> 0.28813758 | E37: =E11/E9 -> 0.2921368 | F37: =F11/F9 -> 0.3243048 | G37: =G11/G9 -> 0.34269533 | I37: =I11/I9 -> 0.33684203 | J37: =J11/J9 -> 0.36271353
A38: R&D % of revenue | C38: =-C14/C9 -> 0.086447453 | D38: =-D14/D9 -> 0.082638923 | E38: =-E14/E9 -> 0.08984414 | F38: =-F14/F9 -> 0.098717828 | G38: =-G14/G9 -> 0.087842876 | I38: =-I14/I9 -> 0.094292054 | J38: =-J14/J9 -> 0.085925907
A39: SG&A % of revenue | C39: =-(C12+C13)/C9 -> 0.10112026 | D39: =-(D12+D13)/D9 -> 0.097362168 | E39: =-(E12+E13)/E9 -> 0.099913622 | F39: =-(F12+F13)/F9 -> 0.1121233 | G39: =-(G12+G13)/G9 -> 0.1028373 | I39: =-(I12+I13)/I9 -> 0.10658659 | J39: =-(J12+J13)/J9 -> 0.10151894
A40: EBIT margin | C40: =C17/C9 -> 0.099674776 | D40: =D17/D9 -> 0.10778917 | E40: =E17/E9 -> 0.10206165 | F40: =F17/F9 -> 0.11314744 | G40: =G17/G9 -> 0.15126026 | I40: =I17/I9 -> 0.13461276 | J40: =J17/J9 -> 0.17217117
A41: EBITDA margin | C41: =C33/C9 -> 0.15418032 | D41: =D33/D9 -> 0.15704526 | E41: =E33/E9 -> 0.15587104 | F41: =F33/F9 -> 0.17254746 | G41: =G33/G9 -> 0.20143111 | I41: =I33/I9 -> 0.19050394 | J41: =J33/J9 -> 0.21951967
A42: Effective tax rate | C42: =-C23/C22 -> 0.20007872 | D42: =-D23/D22 -> 0.19699341 | E42: =-E23/E22 -> 0.20068504 | F42: =-F23/F22 -> 0.21288891 | G42: =-G23/G22 -> 0.22681912 | I42: =-I23/I22 -> 0.22299528 | J42: =-J23/J22 -> 0.228299
A43: Net margin (to parent) | C43: =C26/C9 -> 0.085156622 | D43: =D26/D9 -> 0.084968908 | E43: =E26/E9 -> 0.083226469 | F43: =F26/F9 -> 0.083649012 | G43: =G26/G9 -> 0.10832583 | I43: =I26/I9 -> 0.099520638 | J43: =J26/J9 -> 0.13336272
A44: EPS growth (y/y) | D44: =D29/C29-1 -> 0.21903866 | E44: =E29/D29-1 -> 0.022253813 | F44: =F29/E29-1 -> 0.054979499 | G44: =G29/F29-1 -> 0.70623977 | J44: =J29/I29-1 -> 0.88970832

Sheet BS
A1: Balance sheet
A2: NT$ million, period end. 'Other' lines are the reported subtotal less the lines shown, so each section ties to the reported figure; the Checks sheet tests that total assets equal total liabilities plus equity.
I4: Interim (six months)
A5: NT$ million | B5: Note / source | C5: FY2021A | D5: FY2022A | E5: FY2023A | F5: FY2024A | G5: FY2025A | I5: 1H25A | J5: 1H26A
C6: 31-Dec-21 | D6: 31-Dec-22 | E6: 31-Dec-23 | F6: 31-Dec-24 | G6: 31-Dec-25 | I6: 30-Jun-25 | J6: 30-Jun-26
A8: Assets
A9: Cash and cash equivalents | C9: =Historicals!C33 -> 49855.053 | D9: =Historicals!D33 -> 61546.836 | E9: =Historicals!E33 -> 87455.916 | F9: =Historicals!F33 -> 117459.25 | G9: =Historicals!G33 -> 151172.17 | I9: =Historicals!I33 -> 139527.97 | J9: =Historicals!J33 -> 182350.2
A10: Short-term investments | B10: FVTPL + FVOCI + amortised cost | C10: =Historicals!C34+Historicals!C35+Historicals!C36 -> 1412.967 | D10: =Historicals!D34+Historicals!D35+Historicals!D36 -> 2024.994 | E10: =Historicals!E34+Historicals!E35+Historicals!E36 -> 5163.641 | F10: =Historicals!F34+Historicals!F35+Historicals!F36 -> 4333.292 | G10: =Historicals!G34+Historicals!G35+Historicals!G36 -> 3940.698 | I10: =Historicals!I34+Historicals!I35+Historicals!I36 -> 3821.424 | J10: =Historicals!J34+Historicals!J35+Historicals!J36 -> 4248.855
A11: Receivables | B11: notes + trade + related parties | C11: =Historicals!C38+Historicals!C39+Historicals!C40 -> 70857.01 | D11: =Historicals!D38+Historicals!D39+Historicals!D40 -> 87197.711 | E11: =Historicals!E38+Historicals!E39+Historicals!E40 -> 79379.663 | F11: =Historicals!F38+Historicals!F39+Historicals!F40 -> 89920.501 | G11: =Historicals!G38+Historicals!G39+Historicals!G40 -> 121716.56 | I11: =Historicals!I38+Historicals!I39+Historicals!I40 -> 91443.153 | J11: =Historicals!J38+Historicals!J39+Historicals!J40 -> 142946.77
A12: Inventories | C12: =Historicals!C41 -> 66107.351 | D12: =Historicals!D41 -> 79844.364 | E12: =Historicals!E41 -> 76226.562 | F12: =Historicals!F41 -> 83856.341 | G12: =Historicals!G41 -> 101478.31 | I12: =Historicals!I41 -> 81529.671 | J12: =Historicals!J41 -> 139394.17
A13: Other current assets | B13: incl. contract assets, prepayments, tax | C13: =Historicals!C42-SUM(C9:C12) -> 8645.813 | D13: =Historicals!D42-SUM(D9:D12) -> 9836.561 | E13: =Historicals!E42-SUM(E9:E12) -> 11732.402 | F13: =Historicals!F42-SUM(F9:F12) -> 15355.464 | G13: =Historicals!G42-SUM(G9:G12) -> 17473.042 | I13: =Historicals!I42-SUM(I9:I12) -> 15293.042 | J13: =Historicals!J42-SUM(J9:J12) -> 18109.593
A14: Total current assets | C14: =SUM(C9:C13) -> 196878.19 | D14: =SUM(D9:D13) -> 240450.47 | E14: =SUM(E9:E13) -> 259958.18 | F14: =SUM(F9:F13) -> 310924.85 | G14: =SUM(G9:G13) -> 395780.79 | I14: =SUM(I9:I13) -> 331615.26 | J14: =SUM(J9:J13) -> 487049.6
A15: Long-term investments | C15: =Historicals!C43+Historicals!C44+Historicals!C45+Historicals!C46 -> 5003.372 | D15: =Historicals!D43+Historicals!D44+Historicals!D45+Historicals!D46 -> 4604.61 | E15: =Historicals!E43+Historicals!E44+Historicals!E45+Historicals!E46 -> 3461.828 | F15: =Historicals!F43+Historicals!F44+Historicals!F45+Historicals!F46 -> 3783.828 | G15: =Historicals!G43+Historicals!G44+Historicals!G45+Historicals!G46 -> 3923.243 | I15: =Historicals!I43+Historicals!I44+Historicals!I45+Historicals!I46 -> 3490.199 | J15: =Historicals!J43+Historicals!J44+Historicals!J45+Historicals!J46 -> 7987.657
A16: Property, plant and equipment | C16: =Historicals!C47 -> 76607.285 | D16: =Historicals!D47 -> 86266.587 | E16: =Historicals!E47 -> 98001.515 | F16: =Historicals!F47 -> 115710.42 | G16: =Historicals!G47 -> 142039.84 | I16: =Historicals!I47 -> 117057.73 | J16: =Historicals!J47 -> 158397.55
A17: Right-of-use assets | C17: =Historicals!C48 -> 3006.96 | D17: =Historicals!D48 -> 5086.323 | E17: =Historicals!E48 -> 4834.885 | F17: =Historicals!F48 -> 4511.414 | G17: =Historicals!G48 -> 4559.183 | I17: =Historicals!I48 -> 4319.248 | J17: =Historicals!J48 -> 4903.607
A18: Intangible assets (incl. goodwill) | C18: =Historicals!C50 -> 73609.564 | D18: =Historicals!D50 -> 77169.854 | E18: =Historicals!E50 -> 78544.404 | F18: =Historicals!F50 -> 78782.813 | G18: =Historicals!G50 -> 75326.273 | I18: =Historicals!I50 -> 71869.905 | J18: =Historicals!J50 -> 74962.513
A19: Other non-current assets | B19: incl. deferred tax, investment property | C19: =Historicals!C51-SUM(C15:C18) -> 10006.935 | D19: =Historicals!D51-SUM(D15:D18) -> 12295.966 | E19: =Historicals!E51-SUM(E15:E18) -> 12945.762 | F19: =Historicals!F51-SUM(F15:F18) -> 18184.39 | G19: =Historicals!G51-SUM(G15:G18) -> 17989.271 | I19: =Historicals!I51-SUM(I15:I18) -> 18066.58 | J19: =Historicals!J51-SUM(J15:J18) -> 21132.407
A20: Total non-current assets | C20: =SUM(C15:C19) -> 168234.12 | D20: =SUM(D15:D19) -> 185423.34 | E20: =SUM(E15:E19) -> 197788.39 | F20: =SUM(F15:F19) -> 220972.87 | G20: =SUM(G15:G19) -> 243837.81 | I20: =SUM(I15:I19) -> 214803.66 | J20: =SUM(J15:J19) -> 267383.73
A21: Total assets | C21: =C14+C20 -> 365112.31 | D21: =D14+D20 -> 425873.81 | E21: =E14+E20 -> 457746.58 | F21: =F14+F20 -> 531897.72 | G21: =G14+G20 -> 639618.6 | I21: =I14+I20 -> 546418.92 | J21: =J14+J20 -> 754433.33
A23: Liabilities and equity
A24: Short-term debt | B24: ST borrowings + current portion of LT debt | C24: =Historicals!C53+Historicals!C57 -> 4397.362 | D24: =Historicals!D53+Historicals!D57 -> 2076.762 | E24: =Historicals!E53+Historicals!E57 -> 5874.566 | F24: =Historicals!F53+Historicals!F57 -> 8120.963 | G24: =Historicals!G53+Historicals!G57 -> 17325.012 | I24: =Historicals!I53+Historicals!I57 -> 21805.38 | J24: =Historicals!J53+Historicals!J57 -> 22606.896
A25: Payables | B25: notes + trade + related parties | C25: =Historicals!C54+Historicals!C55+Historicals!C56 -> 54569.925 | D25: =Historicals!D54+Historicals!D55+Historicals!D56 -> 62715.67 | E25: =Historicals!E54+Historicals!E55+Historicals!E56 -> 53538.944 | F25: =Historicals!F54+Historicals!F55+Historicals!F56 -> 69223.251 | G25: =Historicals!G54+Historicals!G55+Historicals!G56 -> 94451.507 | I25: =Historicals!I54+Historicals!I55+Historicals!I56 -> 69448.125 | J25: =Historicals!J54+Historicals!J55+Historicals!J56 -> 116655.06
A26: Other current liabilities | B26: incl. other payables, tax, contract liab., leases | C26: =Historicals!C59-C24-C25 -> 49202.19 | D26: =Historicals!D59-D24-D25 -> 60220.996 | E26: =Historicals!E59-E24-E25 -> 66671.043 | F26: =Historicals!F59-F24-F25 -> 74938.912 | G26: =Historicals!G59-G24-G25 -> 97888.47 | I26: =Historicals!I59-I24-I25 -> 92702.314 | J26: =Historicals!J59-J24-J25 -> 165240.23
A27: Total current liabilities | C27: =SUM(C24:C26) -> 108169.48 | D27: =SUM(D24:D26) -> 125013.43 | E27: =SUM(E24:E26) -> 126084.55 | F27: =SUM(F24:F26) -> 152283.13 | G27: =SUM(G24:G26) -> 209664.99 | I27: =SUM(I24:I26) -> 183955.82 | J27: =SUM(J24:J26) -> 304502.19
A28: Long-term debt | B28: bonds + LT borrowings | C28: =Historicals!C60+Historicals!C61 -> 43913.787 | D28: =Historicals!D60+Historicals!D61 -> 44337.342 | E28: =Historicals!E60+Historicals!E61 -> 51420.422 | F28: =Historicals!F60+Historicals!F61 -> 56308.906 | G28: =Historicals!G60+Historicals!G61 -> 56703.273 | I28: =Historicals!I60+Historicals!I61 -> 58648.36 | J28: =Historicals!J60+Historicals!J61 -> 48031.344
A29: Lease liabilities (non-current) | C29: =Historicals!C62 -> 1366.401 | D29: =Historicals!D62 -> 2302.735 | E29: =Historicals!E62 -> 2555.275 | F29: =Historicals!F62 -> 2217.571 | G29: =Historicals!G62 -> 2495.985 | I29: =Historicals!I62 -> 2377.877 | J29: =Historicals!J62 -> 2713.736
A30: Other non-current liabilities | B30: incl. deferred tax liabilities | C30: =Historicals!C63-C28-C29 -> 25537.987 | D30: =Historicals!D63-D28-D29 -> 28853.116 | E30: =Historicals!E63-E28-E29 -> 34950.835 | F30: =Historicals!F63-F28-F29 -> 41522.778 | G30: =Historicals!G63-G28-G29 -> 45365.35 | I30: =Historicals!I63-I28-I29 -> 40538.997 | J30: =Historicals!J63-J28-J29 -> 48961.168
A31: Total non-current liabilities | C31: =SUM(C28:C30) -> 70818.175 | D31: =SUM(D28:D30) -> 75493.193 | E31: =SUM(E28:E30) -> 88926.532 | F31: =SUM(F28:F30) -> 100049.26 | G31: =SUM(G28:G30) -> 104564.61 | I31: =SUM(I28:I30) -> 101565.23 | J31: =SUM(J28:J30) -> 99706.248
A32: Total liabilities | C32: =C27+C31 -> 178987.65 | D32: =D27+D31 -> 200506.62 | E32: =E27+E31 -> 215011.08 | F32: =F27+F31 -> 252332.38 | G32: =G27+G31 -> 314229.6 | I32: =I27+I31 -> 285521.05 | J32: =J27+J31 -> 404208.44
A33: Equity attributable to owners of the parent | C33: =Historicals!C66 -> 154786.52 | D33: =Historicals!D66 -> 186788.91 | E33: =Historicals!E66 -> 199163.78 | F33: =Historicals!F66 -> 230087.29 | G33: =Historicals!G66 -> 268057.98 | I33: =Historicals!I66 -> 212197.76 | J33: =Historicals!J66 -> 293710.74
A34: Non-controlling interest | C34: =Historicals!C67 -> 31338.136 | D34: =Historicals!D67 -> 38578.278 | E34: =Historicals!E67 -> 43571.715 | F34: =Historicals!F67 -> 49478.05 | G34: =Historicals!G67 -> 57331.027 | I34: =Historicals!I67 -> 48700.102 | J34: =Historicals!J67 -> 56514.152
A35: Total equity | C35: =C33+C34 -> 186124.66 | D35: =D33+D34 -> 225367.18 | E35: =E33+E34 -> 242735.49 | F35: =F33+F34 -> 279565.34 | G35: =G33+G34 -> 325389 | I35: =I33+I34 -> 260897.86 | J35: =J33+J34 -> 350224.89
A36: Total liabilities and equity | C36: =C32+C35 -> 365112.31 | D36: =D32+D35 -> 425873.81 | E36: =E32+E35 -> 457746.58 | F36: =F32+F35 -> 531897.72 | G36: =G32+G35 -> 639618.6 | I36: =I32+I35 -> 546418.92 | J36: =J32+J35 -> 754433.33
A37: Balance check: assets - (liabilities + equity) | B37: must be zero | C37: =C21-C36 -> 0 | D37: =D21-D36 -> 0 | E37: =E21-E36 -> 0 | F37: =F21-F36 -> 0 | G37: =G21-G36 -> 0 | I37: =I21-I36 -> 0 | J37: =J21-J36 -> 0
A39: Memo
A40: Total debt | C40: =C24+C28 -> 48311.149 | D40: =D24+D28 -> 46414.104 | E40: =E24+E28 -> 57294.988 | F40: =F24+F28 -> 64429.869 | G40: =G24+G28 -> 74028.285 | I40: =I24+I28 -> 80453.74 | J40: =J24+J28 -> 70638.24
A41: Net debt / (net cash) | B41: debt - cash - ST investments; excl. leases | C41: =C40-C9-C10 -> -2956.871 | D41: =D40-D9-D10 -> -17157.726 | E41: =E40-E9-E10 -> -35324.569 | F41: =F40-F9-F10 -> -57362.673 | G41: =G40-G9-G10 -> -81084.588 | I41: =I40-I9-I10 -> -62895.652 | J41: =J40-J9-J10 -> -115960.82
A42: Trade working capital | B42: receivables + inventories - payables | C42: =C11+C12-C25 -> 82394.436 | D42: =D11+D12-D25 -> 104326.4 | E42: =E11+E12-E25 -> 102067.28 | F42: =F11+F12-F25 -> 104553.59 | G42: =G11+G12-G25 -> 128743.37 | I42: =I11+I12-I25 -> 103524.7 | J42: =J11+J12-J25 -> 165685.89

Sheet CF
A1: Cash flow statement
A2: NT$ million. Indirect method as reported (Taiwan IFRS: interest and tax paid sit in operating cash flow). 'Other' lines tie each section to the reported total; closing cash is tested against the balance sheet on the Checks sheet.
I4: Interim (six months)
A5: NT$ million | B5: Note / source | C5: FY2021A | D5: FY2022A | E5: FY2023A | F5: FY2024A | G5: FY2025A | I5: 1H25A | J5: 1H26A
C6: 31-Dec-21 | D6: 31-Dec-22 | E6: 31-Dec-23 | F6: 31-Dec-24 | G6: 31-Dec-25 | I6: 30-Jun-25 | J6: 30-Jun-26
A8: Operating activities
A9: Profit before tax | C9: =Historicals!C72 -> 35627.547 | D9: =Historicals!D72 -> 46065.298 | E9: =Historicals!E72 -> 48642.111 | F9: =Historicals!F72 -> 51315.628 | G9: =Historicals!G72 -> 87865.996 | I9: =Historicals!I72 -> 35234.087 | J9: =Historicals!J72 -> 66092.437
A10: Depreciation and amortisation | C10: =Historicals!C73+Historicals!C74 -> 17151.303 | D10: =Historicals!D73+Historicals!D74 -> 18936.175 | E10: =Historicals!E73+Historicals!E74 -> 21589.753 | F10: =Historicals!F73+Historicals!F74 -> 25016.172 | G10: =Historicals!G73+Historicals!G74 -> 27839.061 | I10: =Historicals!I73+Historicals!I74 -> 13579.013 | J10: =Historicals!J73+Historicals!J74 -> 16222.01
A11: (Increase) decrease in accounts receivable | C11: =Historicals!C75 -> -7683.037 | D11: =Historicals!D75 -> -15664.563 | E11: =Historicals!E75 -> 7245.438 | F11: =Historicals!F75 -> -10404.087 | G11: =Historicals!G75 -> -31992.341 | I11: =Historicals!I75 -> -2524.48 | J11: =Historicals!J75 -> -21685.625
A12: (Increase) decrease in inventories | C12: =Historicals!C76 -> -20873.744 | D12: =Historicals!D76 -> -12320.867 | E12: =Historicals!E76 -> 4132.104 | F12: =Historicals!F76 -> -7629.779 | G12: =Historicals!G76 -> -17509.757 | I12: =Historicals!I76 -> 2390.161 | J12: =Historicals!J76 -> -37836.259
A13: Increase (decrease) in accounts payable | C13: =Historicals!C77 -> 7740.285 | D13: =Historicals!D77 -> 7613.266 | E13: =Historicals!E77 -> -9826.389 | F13: =Historicals!F77 -> 15692.167 | G13: =Historicals!G77 -> 25200.018 | I13: =Historicals!I77 -> 230.123 | J13: =Historicals!J77 -> 22151.921
A14: Interest paid | C14: =Historicals!C78 -> -295.484 | D14: =Historicals!D78 -> -486.748 | E14: =Historicals!E78 -> -952.693 | F14: =Historicals!F78 -> -1471.457 | G14: =Historicals!G78 -> -1514.99 | I14: =Historicals!I78 -> -817.825 | J14: =Historicals!J78 -> -770.244
A15: Income taxes paid | C15: =Historicals!C79 -> -5468.923 | D15: =Historicals!D79 -> -6109.584 | E15: =Historicals!E79 -> -7026.581 | F15: =Historicals!F79 -> -8835.807 | G15: =Historicals!G79 -> -8982.596 | I15: =Historicals!I79 -> -4717.949 | J15: =Historicals!J79 -> -9608.76
A16: Other operating items | B16: non-cash items, other WC, interest received | C16: =Historicals!C80-SUM(C9:C15) -> 2121.419 | D16: =Historicals!D80-SUM(D9:D15) -> 8496.131 | E16: =Historicals!E80-SUM(E9:E15) -> 7282.67 | F16: =Historicals!F80-SUM(F9:F15) -> 9212.12 | G16: =Historicals!G80-SUM(G9:G15) -> 17568.89 | I16: =Historicals!I80-SUM(I9:I15) -> 220.444 | J16: =Historicals!J80-SUM(J9:J15) -> 28535.123
A17: Cash flow from operations | C17: =SUM(C9:C16) -> 28319.366 | D17: =SUM(D9:D16) -> 46529.108 | E17: =SUM(E9:E16) -> 71086.413 | F17: =SUM(F9:F16) -> 72894.957 | G17: =SUM(G9:G16) -> 98474.281 | I17: =SUM(I9:I16) -> 43593.574 | J17: =SUM(J9:J16) -> 63100.603
A19: Investing activities
A20: Purchase of PP&E | C20: =Historicals!C81 -> -23027.29 | D20: =Historicals!D81 -> -21824.042 | E20: =Historicals!E81 -> -27829.767 | F20: =Historicals!F81 -> -33429.953 | G20: =Historicals!G81 -> -45722.154 | I20: =Historicals!I81 -> -19041.227 | J20: =Historicals!J81 -> -27252.368
A21: Disposal of PP&E | C21: =Historicals!C82 -> 212.445 | D21: =Historicals!D82 -> 843.099 | E21: =Historicals!E82 -> 51.934 | F21: =Historicals!F82 -> 50.167 | G21: =Historicals!G82 -> 141.76 | I21: =Historicals!I82 -> 22.601 | J21: =Historicals!J82 -> 38.154
A22: Purchase of intangible assets | C22: =Historicals!C83 -> -1300.978 | D22: =Historicals!D83 -> -615.536 | E22: =Historicals!E83 -> -469.89 | F22: =Historicals!F83 -> -1644.428 | G22: =Historicals!G83 -> -1430.633 | I22: =Historicals!I83 -> -1024.771 | J22: =Historicals!J83 -> -564.395
A23: Acquisitions, net of cash acquired | C23: =Historicals!C84 -> -2874.959 | D23: =Historicals!D84 -> -2625.458 | E23: =Historicals!E84 -> -5629.812 | F23: =Historicals!F84 -> 0 | G23: =Historicals!G84 -> -2107.562 | I23: =Historicals!I84 -> 0 | J23: =Historicals!J84 -> -762.405
A24: Other investing items | B24: financial assets, prepayments, other | C24: =Historicals!C85-SUM(C20:C23) -> 509.523 | D24: =Historicals!D85-SUM(D20:D23) -> -497.306 | E24: =Historicals!E85-SUM(E20:E23) -> 375.842 | F24: =Historicals!F85-SUM(F20:F23) -> -5335.809 | G24: =Historicals!G85-SUM(G20:G23) -> -4095.617 | I24: =Historicals!I85-SUM(I20:I23) -> -2205.553 | J24: =Historicals!J85-SUM(J20:J23) -> -1741.441
A25: Cash flow from investing | C25: =SUM(C20:C24) -> -26481.259 | D25: =SUM(D20:D24) -> -24719.243 | E25: =SUM(E20:E24) -> -33501.693 | F25: =SUM(F20:F24) -> -40360.023 | G25: =SUM(G20:G24) -> -53214.206 | I25: =SUM(I20:I24) -> -22248.95 | J25: =SUM(J20:J24) -> -30282.455
A27: Financing activities
A28: Net borrowing / (repayment) | B28: ST + bonds + LT borrowings, net | C28: =Historicals!C86+Historicals!C87+Historicals!C88+Historicals!C89+Historicals!C90 -> 6992.635 | D28: =Historicals!D86+Historicals!D87+Historicals!D88+Historicals!D89+Historicals!D90 -> -1899.746 | E28: =Historicals!E86+Historicals!E87+Historicals!E88+Historicals!E89+Historicals!E90 -> 10326.588 | F28: =Historicals!F86+Historicals!F87+Historicals!F88+Historicals!F89+Historicals!F90 -> 7134.881 | G28: =Historicals!G86+Historicals!G87+Historicals!G88+Historicals!G89+Historicals!G90 -> 11728.748 | I28: =Historicals!I86+Historicals!I87+Historicals!I88+Historicals!I89+Historicals!I90 -> 19769.593 | J28: =Historicals!J86+Historicals!J87+Historicals!J88+Historicals!J89+Historicals!J90 -> -4004.173
A29: Lease principal repaid | C29: =Historicals!C91 -> -541.768 | D29: =Historicals!D91 -> -1940.165 | E29: =Historicals!E91 -> -816.154 | F29: =Historicals!F91 -> -623.183 | G29: =Historicals!G91 -> -882.728 | I29: =Historicals!I91 -> -575.211 | J29: =Historicals!J91 -> -434.197
A30: Dividends paid to shareholders | B30: paid in Q3; nil in 1H | C30: =Historicals!C92 -> -14286.48 | D30: =Historicals!D92 -> -14286.479 | E30: =Historicals!E92 -> -25559.802 | F30: =Historicals!F92 -> -16702.171 | G30: =Historicals!G92 -> -18182.803 | I30: =Historicals!I92 -> 0 | J30: =Historicals!J92 -> 0
A31: Dividends paid to non-controlling interests | C31: =Historicals!C93 -> -1464.506 | D31: =Historicals!D93 -> -739.023 | E31: =Historicals!E93 -> -1895.556 | F31: =Historicals!F93 -> -1993.839 | G31: =Historicals!G93 -> -2129.914 | I31: =Historicals!I93 -> -2043.802 | J31: =Historicals!J93 -> -2725.886
A32: Other financing items | B32: deposits, NCI transactions | C32: =Historicals!C94-SUM(C28:C31) -> 963.259 | D32: =Historicals!D94-SUM(D28:D31) -> -873.759 | E32: =Historicals!E94-SUM(E28:E31) -> 7466.862 | F32: =Historicals!F94-SUM(F28:F31) -> 1066.73 | G32: =Historicals!G94-SUM(G28:G31) -> 65.3 | I32: =Historicals!I94-SUM(I28:I31) -> 43.326 | J32: =Historicals!J94-SUM(J28:J31) -> 4544.632
A33: Cash flow from financing | C33: =SUM(C28:C32) -> -8336.86 | D33: =SUM(D28:D32) -> -19739.172 | E33: =SUM(E28:E32) -> -10478.062 | F33: =SUM(F28:F32) -> -11117.582 | G33: =SUM(G28:G32) -> -9401.397 | I33: =SUM(I28:I32) -> 17193.906 | J33: =SUM(J28:J32) -> -2619.624
A35: Effect of exchange rates | C35: =Historicals!C95 -> -2358.179 | D35: =Historicals!D95 -> 9621.09 | E35: =Historicals!E95 -> -1197.578 | F35: =Historicals!F95 -> 8585.982 | G35: =Historicals!G95 -> -2145.753 | I35: =Historicals!I95 -> -16469.812 | J35: =Historicals!J95 -> 979.505
A36: Net change in cash | C36: =C17+C25+C33+C35 -> -8856.932 | D36: =D17+D25+D33+D35 -> 11691.783 | E36: =E17+E25+E33+E35 -> 25909.08 | F36: =F17+F25+F33+F35 -> 30003.334 | G36: =G17+G25+G33+G35 -> 33712.925 | I36: =I17+I25+I33+I35 -> 22068.718 | J36: =J17+J25+J33+J35 -> 31178.029
A37: Cash at beginning of period | B37: prior balance sheet; FY2021 from CF | C37: =Historicals!C97 -> 58711.985 | D37: =BS!C9 -> 49855.053 | E37: =BS!D9 -> 61546.836 | F37: =BS!E9 -> 87455.916 | G37: =BS!F9 -> 117459.25 | I37: =BS!F9 -> 117459.25 | J37: =BS!G9 -> 151172.17
A38: Cash at end of period | C38: =C37+C36 -> 49855.053 | D38: =D37+D36 -> 61546.836 | E38: =E37+E36 -> 87455.916 | F38: =F37+F36 -> 117459.25 | G38: =G37+G36 -> 151172.17 | I38: =I37+I36 -> 139527.97 | J38: =J37+J36 -> 182350.2
A40: Memo
A41: Capex (PP&E + intangibles) | B41: decision D4 | C41: =C20+C22 -> -24328.268 | D41: =D20+D22 -> -22439.578 | E41: =E20+E22 -> -28299.657 | F41: =F20+F22 -> -35074.381 | G41: =G20+G22 -> -47152.787 | I41: =I20+I22 -> -20065.998 | J41: =J20+J22 -> -27816.763
A42: Free cash flow (CFO + capex) | C42: =C17+C41 -> 3991.098 | D42: =D17+D41 -> 24089.53 | E42: =E17+E41 -> 42786.756 | F42: =F17+F41 -> 37820.576 | G42: =G17+G41 -> 51321.494 | I42: =I17+I41 -> 23527.576 | J42: =J17+J41 -> 35283.84
A43: FCF margin | C43: =C42/IS!C9 -> 0.012683408 | D43: =D42/IS!D9 -> 0.062660812 | E43: =E42/IS!E9 -> 0.10663991 | F43: =F42/IS!F9 -> 0.089803622 | G43: =G42/IS!G9 -> 0.092490297 | I43: =I42/IS!I9 -> 0.096839436 | J43: =J42/IS!J9 -> 0.10298582
A44: Cash conversion (CFO / net income) | C44: =C17/IS!C24 -> 0.99368871 | D44: =D17/IS!D24 -> 1.2578583 | E44: =E17/IS!E24 -> 1.828337 | F44: =F17/IS!F24 -> 1.8047282 | G44: =G17/IS!G24 -> 1.4495089 | I44: =I17/IS!I24 -> 1.59234 | J44: =J17/IS!J24 -> 1.2371794

Sheet Schedules
A1: Supporting schedules (historical)
A2: NT$ million unless stated. Fiscal years only; ratios use year-end balances. These historical ratios anchor the forecast drivers set on the Assumptions sheet in M3.
A4: Days in year | B4: 365
A5: NT$ million | B5: Note / source | C5: FY2021A | D5: FY2022A | E5: FY2023A | F5: FY2024A | G5: FY2025A
C6: 31-Dec-21 | D6: 31-Dec-22 | E6: 31-Dec-23 | F6: 31-Dec-24 | G6: 31-Dec-25
A8: Working capital
A9: Revenue | C9: =IS!C9 -> 314670.8 | D9: =IS!D9 -> 384443.31 | E9: =IS!E9 -> 401226.5 | F9: =IS!F9 -> 421147.56 | G9: =IS!G9 -> 554885.17
A10: Cost of revenue (positive) | C10: =-IS!C10 -> 224461.35 | D10: =-IS!D10 -> 273670.74 | E10: =-IS!E10 -> 284013.47 | F10: =-IS!F10 -> 284567.38 | G10: =-IS!G10 -> 364728.61
A11: Receivables | C11: =BS!C11 -> 70857.01 | D11: =BS!D11 -> 87197.711 | E11: =BS!E11 -> 79379.663 | F11: =BS!F11 -> 89920.501 | G11: =BS!G11 -> 121716.56
A12: Inventories | C12: =BS!C12 -> 66107.351 | D12: =BS!D12 -> 79844.364 | E12: =BS!E12 -> 76226.562 | F12: =BS!F12 -> 83856.341 | G12: =BS!G12 -> 101478.31
A13: Payables | C13: =BS!C25 -> 54569.925 | D13: =BS!D25 -> 62715.67 | E13: =BS!E25 -> 53538.944 | F13: =BS!F25 -> 69223.251 | G13: =BS!G25 -> 94451.507
A14: Receivable days (DSO) | C14: =C11/C9*$B$4 -> 82.190051 | D14: =D11/D9*$B$4 -> 82.787667 | E14: =E11/E9*$B$4 -> 72.212521 | F14: =F11/F9*$B$4 -> 77.932265 | G14: =G11/G9*$B$4 -> 80.064396
A15: Inventory days (DIO) | C15: =C12/C10*$B$4 -> 107.49817 | D15: =D12/D10*$B$4 -> 106.48998 | E15: =E12/E10*$B$4 -> 97.962589 | F15: =F12/F10*$B$4 -> 107.55823 | G15: =G12/G10*$B$4 -> 101.55382
A16: Payable days (DPO) | C16: =C13/C10*$B$4 -> 88.736983 | D16: =D13/D10*$B$4 -> 83.64511 | E16: =E13/E10*$B$4 -> 68.80559 | F16: =F13/F10*$B$4 -> 88.789117 | G16: =G13/G10*$B$4 -> 94.521787
A17: Cash conversion cycle (days) | C17: =C14+C15-C16 -> 100.95123 | D17: =D14+D15-D16 -> 105.63254 | E17: =E14+E15-E16 -> 101.36952 | F17: =F14+F15-F16 -> 96.701379 | G17: =G14+G15-G16 -> 87.096426
A18: Other current assets % revenue | C18: =BS!C13/C9 -> 0.02747574 | D18: =BS!D13/D9 -> 0.025586506 | E18: =BS!E13/E9 -> 0.029241344 | F18: =BS!F13/F9 -> 0.036461007 | G18: =BS!G13/G9 -> 0.031489474
A19: Other current liabilities % revenue | C19: =BS!C26/C9 -> 0.15636084 | D19: =BS!D26/D9 -> 0.15664467 | E19: =BS!E26/E9 -> 0.16616809 | F19: =BS!F26/F9 -> 0.1779398 | G19: =BS!G26/G9 -> 0.17641212
A21: PP&E roll-forward
A22: Opening PP&E | D22: =BS!C16 -> 76607.285 | E22: =BS!D16 -> 86266.587 | F22: =BS!E16 -> 98001.515 | G22: =BS!F16 -> 115710.42
A23: Add: purchases of PP&E | C23: =-CF!C20 -> 23027.29 | D23: =-CF!D20 -> 21824.042 | E23: =-CF!E20 -> 27829.767 | F23: =-CF!F20 -> 33429.953 | G23: =-CF!G20 -> 45722.154
A24: Less: depreciation | B24: all depreciation incl. right-of-use | C24: =-Historicals!C73 -> -13467.401 | D24: =-Historicals!D73 -> -15020.243 | E24: =-Historicals!E73 -> -17577.068 | F24: =-Historicals!F73 -> -21094.536 | G24: =-Historicals!G73 -> -24022.324
A25: Other movements (plug) | B25: disposals, FX, M&A, add-back of ROU depreciation | D25: =BS!D16-D22-D23-D24 -> 2855.503 | E25: =BS!E16-E22-E23-E24 -> 1482.229 | F25: =BS!F16-F22-F23-F24 -> 5373.492 | G25: =BS!G16-G22-G23-G24 -> 4629.589
A26: Closing PP&E | C26: =BS!C16 -> 76607.285 | D26: =BS!D16 -> 86266.587 | E26: =BS!E16 -> 98001.515 | F26: =BS!F16 -> 115710.42 | G26: =BS!G16 -> 142039.84
A27: PP&E capex % revenue | C27: =C23/C9 -> 0.073178987 | D27: =D23/D9 -> 0.056767907 | E27: =E23/E9 -> 0.069361737 | F27: =F23/F9 -> 0.079378243 | G27: =G23/G9 -> 0.082399308
A28: Total capex (PP&E + intangibles) % revenue | C28: =-CF!C41/C9 -> 0.077313396 | D28: =-CF!D41/D9 -> 0.058369017 | E28: =-CF!E41/E9 -> 0.070532871 | F28: =-CF!F41/F9 -> 0.083282879 | G28: =-CF!G41/G9 -> 0.084977559
A29: Depreciation % opening PP&E | D29: =-D24/D22 -> 0.19606808 | E29: =-E24/E22 -> 0.20375291 | F29: =-F24/F22 -> 0.21524704 | G29: =-G24/G22 -> 0.20760726
A30: D&A % revenue | C30: =IS!C32/C9 -> 0.054505544 | D30: =IS!D32/D9 -> 0.049256092 | E30: =IS!E32/E9 -> 0.053809389 | F30: =IS!F32/F9 -> 0.059400017 | G30: =IS!G32/G9 -> 0.050170851
A31: Capex / D&A | C31: =-CF!C41/IS!C32 -> 1.4184501 | D31: =-CF!D41/IS!D32 -> 1.1850111 | E31: =-CF!E41/IS!E32 -> 1.3107911 | F31: =-CF!F41/IS!F32 -> 1.4020683 | G31: =-CF!G41/IS!G32 -> 1.6937636
A33: Intangibles
A34: Amortisation | C34: =Historicals!C74 -> 3683.902 | D34: =Historicals!D74 -> 3915.932 | E34: =Historicals!E74 -> 4012.685 | F34: =Historicals!F74 -> 3921.636 | G34: =Historicals!G74 -> 3816.737
A35: Purchases of intangibles | C35: =-CF!C22 -> 1300.978 | D35: =-CF!D22 -> 615.536 | E35: =-CF!E22 -> 469.89 | F35: =-CF!F22 -> 1644.428 | G35: =-CF!G22 -> 1430.633
A36: Intangible assets (incl. goodwill) | C36: =BS!C18 -> 73609.564 | D36: =BS!D18 -> 77169.854 | E36: =BS!E18 -> 78544.404 | F36: =BS!F18 -> 78782.813 | G36: =BS!G18 -> 75326.273
A38: Debt and interest
A39: Total debt | C39: =BS!C40 -> 48311.149 | D39: =BS!D40 -> 46414.104 | E39: =BS!E40 -> 57294.988 | F39: =BS!F40 -> 64429.869 | G39: =BS!G40 -> 74028.285
A40: Average debt | D40: =AVERAGE(C39,D39) -> 47362.626 | E40: =AVERAGE(D39,E39) -> 51854.546 | F40: =AVERAGE(E39,F39) -> 60862.429 | G40: =AVERAGE(F39,G39) -> 69229.077
A41: Finance costs | B41: incl. lease interest | C41: =-IS!C19 -> 295.157 | D41: =-IS!D19 -> 571.44 | E41: =-IS!E19 -> 1170.718 | F41: =-IS!F19 -> 1547.313 | G41: =-IS!G19 -> 2216.008
A42: Implied cost of debt | D42: =D41/D40 -> 0.012065209 | E42: =E41/E40 -> 0.02257696 | F42: =F41/F40 -> 0.025423123 | G42: =G41/G40 -> 0.032009787
A43: Cash and cash equivalents | C43: =BS!C9 -> 49855.053 | D43: =BS!D9 -> 61546.836 | E43: =BS!E9 -> 87455.916 | F43: =BS!F9 -> 117459.25 | G43: =BS!G9 -> 151172.17
A44: Average cash | D44: =AVERAGE(C43,D43) -> 55700.944 | E44: =AVERAGE(D43,E43) -> 74501.376 | F44: =AVERAGE(E43,F43) -> 102457.58 | G44: =AVERAGE(F43,G43) -> 134315.71
A45: Interest income | C45: =IS!C18 -> 429.643 | D45: =IS!D18 -> 609.613 | E45: =IS!E18 -> 2070.115 | F45: =IS!F18 -> 3406.797 | G45: =IS!G18 -> 3716.575
...

Sheet Checks
A1: Model integrity checks
A2: Every check must be TRUE. Tolerance in NT$ million (B3) and NT$ per share (B4). The overall result rolls up to the Cover sheet.
A3: Tolerance (NT$ m) | B3: 0.01
A4: EPS tolerance (NT$) | B4: 0.02 | I4: Interim (six months)
A5: NT$ million | B5: Note / source | C5: FY2021A | D5: FY2022A | E5: FY2023A | F5: FY2024A | G5: FY2025A | I5: 1H25A | J5: 1H26A | L5: All periods
C6: 31-Dec-21 | D6: 31-Dec-22 | E6: 31-Dec-23 | F6: 31-Dec-24 | G6: 31-Dec-25 | I6: 30-Jun-25 | J6: 30-Jun-26
A8: Balance sheet
A9: Assets = liabilities + equity | C9: =ABS(BS!C37)<=$B$3 -> TRUE | D9: =ABS(BS!D37)<=$B$3 -> TRUE | E9: =ABS(BS!E37)<=$B$3 -> TRUE | F9: =ABS(BS!F37)<=$B$3 -> TRUE | G9: =ABS(BS!G37)<=$B$3 -> TRUE | I9: =ABS(BS!I37)<=$B$3 -> TRUE | J9: =ABS(BS!J37)<=$B$3 -> TRUE | L9: =AND(C9,D9,E9,F9,G9,I9,J9) -> TRUE
A10: Total assets = reported | C10: =ABS(BS!C21-Historicals!C52)<=$B$3 -> TRUE | D10: =ABS(BS!D21-Historicals!D52)<=$B$3 -> TRUE | E10: =ABS(BS!E21-Historicals!E52)<=$B$3 -> TRUE | F10: =ABS(BS!F21-Historicals!F52)<=$B$3 -> TRUE | G10: =ABS(BS!G21-Historicals!G52)<=$B$3 -> TRUE | I10: =ABS(BS!I21-Historicals!I52)<=$B$3 -> TRUE | J10: =ABS(BS!J21-Historicals!J52)<=$B$3 -> TRUE | L10: =AND(C10,D10,E10,F10,G10,I10,J10) -> TRUE
A11: Total liabilities = reported | C11: =ABS(BS!C32-Historicals!C64)<=$B$3 -> TRUE | D11: =ABS(BS!D32-Historicals!D64)<=$B$3 -> TRUE | E11: =ABS(BS!E32-Historicals!E64)<=$B$3 -> TRUE | F11: =ABS(BS!F32-Historicals!F64)<=$B$3 -> TRUE | G11: =ABS(BS!G32-Historicals!G64)<=$B$3 -> TRUE | I11: =ABS(BS!I32-Historicals!I64)<=$B$3 -> TRUE | J11: =ABS(BS!J32-Historicals!J64)<=$B$3 -> TRUE | L11: =AND(C11,D11,E11,F11,G11,I11,J11) -> TRUE
A12: Total equity = reported | C12: =ABS(BS!C35-Historicals!C68)<=$B$3 -> TRUE | D12: =ABS(BS!D35-Historicals!D68)<=$B$3 -> TRUE | E12: =ABS(BS!E35-Historicals!E68)<=$B$3 -> TRUE | F12: =ABS(BS!F35-Historicals!F68)<=$B$3 -> TRUE | G12: =ABS(BS!G35-Historicals!G68)<=$B$3 -> TRUE | I12: =ABS(BS!I35-Historicals!I68)<=$B$3 -> TRUE | J12: =ABS(BS!J35-Historicals!J68)<=$B$3 -> TRUE | L12: =AND(C12,D12,E12,F12,G12,I12,J12) -> TRUE
A14: Income statement
A15: Gross profit = reported | C15: =ABS(IS!C11-Historicals!C11)<=$B$3 -> TRUE | D15: =ABS(IS!D11-Historicals!D11)<=$B$3 -> TRUE | E15: =ABS(IS!E11-Historicals!E11)<=$B$3 -> TRUE | F15: =ABS(IS!F11-Historicals!F11)<=$B$3 -> TRUE | G15: =ABS(IS!G11-Historicals!G11)<=$B$3 -> TRUE | I15: =ABS(IS!I11-Historicals!I11)<=$B$3 -> TRUE | J15: =ABS(IS!J11-Historicals!J11)<=$B$3 -> TRUE | L15: =AND(C15,D15,E15,F15,G15,I15,J15) -> TRUE
A16: Operating expenses = reported | C16: =ABS(IS!C16-Historicals!C16)<=$B$3 -> TRUE | D16: =ABS(IS!D16-Historicals!D16)<=$B$3 -> TRUE | E16: =ABS(IS!E16-Historicals!E16)<=$B$3 -> TRUE | F16: =ABS(IS!F16-Historicals!F16)<=$B$3 -> TRUE | G16: =ABS(IS!G16-Historicals!G16)<=$B$3 -> TRUE | I16: =ABS(IS!I16-Historicals!I16)<=$B$3 -> TRUE | J16: =ABS(IS!J16-Historicals!J16)<=$B$3 -> TRUE | L16: =AND(C16,D16,E16,F16,G16,I16,J16) -> TRUE
A17: EBIT = reported | C17: =ABS(IS!C17-Historicals!C17)<=$B$3 -> TRUE | D17: =ABS(IS!D17-Historicals!D17)<=$B$3 -> TRUE | E17: =ABS(IS!E17-Historicals!E17)<=$B$3 -> TRUE | F17: =ABS(IS!F17-Historicals!F17)<=$B$3 -> TRUE | G17: =ABS(IS!G17-Historicals!G17)<=$B$3 -> TRUE | I17: =ABS(IS!I17-Historicals!I17)<=$B$3 -> TRUE | J17: =ABS(IS!J17-Historicals!J17)<=$B$3 -> TRUE | L17: =AND(C17,D17,E17,F17,G17,I17,J17) -> TRUE
A18: Non-operating total = reported | C18: =ABS(IS!C21-Historicals!C23)<=$B$3 -> TRUE | D18: =ABS(IS!D21-Historicals!D23)<=$B$3 -> TRUE | E18: =ABS(IS!E21-Historicals!E23)<=$B$3 -> TRUE | F18: =ABS(IS!F21-Historicals!F23)<=$B$3 -> TRUE | G18: =ABS(IS!G21-Historicals!G23)<=$B$3 -> TRUE | I18: =ABS(IS!I21-Historicals!I23)<=$B$3 -> TRUE | J18: =ABS(IS!J21-Historicals!J23)<=$B$3 -> TRUE | L18: =AND(C18,D18,E18,F18,G18,I18,J18) -> TRUE
A19: Profit before tax = reported | C19: =ABS(IS!C22-Historicals!C24)<=$B$3 -> TRUE | D19: =ABS(IS!D22-Historicals!D24)<=$B$3 -> TRUE | E19: =ABS(IS!E22-Historicals!E24)<=$B$3 -> TRUE | F19: =ABS(IS!F22-Historicals!F24)<=$B$3 -> TRUE | G19: =ABS(IS!G22-Historicals!G24)<=$B$3 -> TRUE | I19: =ABS(IS!I22-Historicals!I24)<=$B$3 -> TRUE | J19: =ABS(IS!J22-Historicals!J24)<=$B$3 -> TRUE | L19: =AND(C19,D19,E19,F19,G19,I19,J19) -> TRUE
